<mujoco model="iiwa_wsg_paddle_ball">
  <compiler angle="radian" autolimits="true"/>
  <option timestep="0.001" gravity="0 0 -9.81" integrator="implicitfast" cone="elliptic"/>
  <size njmax="2000" nconmax="400"/>

  <default>
    <joint damping="0.5" armature="0.0"/>
    <geom contype="0" conaffinity="0" friction="0.9 0.05 0.01" solimp="0.95 0.99 0.001" solref="0.005 1"/>
    <motor ctrllimited="true"/>
  </default>

  <visual>
    <headlight diffuse="0.85 0.85 0.85" ambient="0.35 0.35 0.35" specular="0.1 0.1 0.1"/>
    <map znear="0.01"/>
  </visual>

  <asset>
    <mesh name="m_link_0" file="assets/link_0.obj"/>
    <mesh name="m_link_1" file="assets/link_1.obj"/>
    <mesh name="m_link_2_orange" file="assets/link_2_orange.obj"/>
    <mesh name="m_link_2_grey" file="assets/link_2_grey.obj"/>
    <mesh name="m_link_3" file="assets/link_3.obj"/>
    <mesh name="m_link_4_orange" file="assets/link_4_orange.obj"/>
    <mesh name="m_link_4_grey" file="assets/link_4_grey.obj"/>
    <mesh name="m_link_5" file="assets/link_5.obj"/>
    <mesh name="m_link_6_orange" file="assets/link_6_orange.obj"/>
    <mesh name="m_link_6_grey" file="assets/link_6_grey.obj"/>
    <mesh name="m_link_7" file="assets/link_7.obj"/>
    <mesh name="m_band" file="assets/band.obj"/>
    <mesh name="m_kuka" file="assets/kuka.obj"/>
    <mesh name="m_wsg_body" file="assets/wsg_body.obj"/>
    <mesh name="m_wsg_finger" file="assets/wsg_finger_with_tip.obj"/>

    <texture name="checker" type="2d" builtin="checker" width="512" height="512"
             rgb1="0.17 0.21 0.30" rgb2="0.12 0.15 0.22"/>
    <material name="floor_mat" texture="checker" reflectance="0.1" texrepeat="6 6"/>
    <material name="iiwa_gray" rgba="0.40 0.40 0.40 1"/>
    <material name="iiwa_orange" rgba="1.0 0.423529 0.039216 1"/>
    <material name="iiwa_silver" rgba="0.6 0.6 0.6 1"/>
    <material name="iiwa_black" rgba="0.0 0.0 0.0 1"/>
    <material name="wsg_mat" rgba="0.30 0.30 0.33 1"/>
    <material name="paddle_mat" rgba="1 0.423529 0.039216 1"/>
    <material name="ball_mat" rgba="0.92 0.92 0.92 1"/>
  </asset>

  <worldbody>
    <light name="key" pos="1.2 0 2.2" dir="-1 0 -1"/>
    <geom name="floor" type="plane" size="8 8 0.1" material="floor_mat"
          contype="1" conaffinity="1" friction="0.9 0.02 0.01" solref="0.015 0.1"/>

    <geom name="iiwa_base_geom" size="0.139 0.085" pos="-0.015 0 0.07" type="cylinder" rgba="0 0 0 0"/>
    <geom name="iiwa_link_0_visual" type="mesh" mesh="m_link_0" material="iiwa_gray"/>

    <body name="iiwa_link_1" pos="0 0 0.1575">
      <inertial pos="0 -0.03 0.12" quat="0.707107 0 0 0.707107" mass="5.76" diaginertia="0.0333 0.033 0.0123"/>
      <joint name="iiwa_joint_1" axis="0 0 1" range="-2.96705972839 2.96705972839" damping="0.5" armature="0.0"/>
      <geom name="iiwa_link_1_geom" size="0.101 0.145" pos="0 -0.014 0.14" type="cylinder" rgba="0 0 0 0"/>
      <geom name="iiwa_link_1_visual" type="mesh" mesh="m_link_1" material="iiwa_gray"/>

      <body name="iiwa_link_2" pos="0 0 0.2025" quat="0 0 0.707107 0.707107">
        <inertial pos="0.0003 0.059 0.042" mass="6.35" diaginertia="0.0305 0.0304 0.011"/>
        <joint name="iiwa_joint_2" axis="0 0 1" range="-2.09439510239 2.09439510239" damping="0.5" armature="0.0"/>
        <geom name="iiwa_link_2_geom" size="0.101 0.145" pos="0 0.056 0.035" quat="0.707107 0.707107 0 0" type="cylinder" rgba="0 0 0 0"/>
        <geom name="iiwa_link_2_visual_orange" type="mesh" mesh="m_link_2_orange" material="iiwa_orange"/>
        <geom name="iiwa_link_2_visual_grey" type="mesh" mesh="m_link_2_grey" material="iiwa_gray"/>

        <body name="iiwa_link_3" pos="0 0.2045 0" quat="0 0 0.707107 0.707107">
          <inertial pos="0 0.03 0.13" mass="3.5" diaginertia="0.025 0.0238 0.0076"/>
          <joint name="iiwa_joint_3" axis="0 0 1" range="-2.96705972839 2.96705972839" damping="0.5" armature="0.0"/>
          <geom name="iiwa_link_3_geom" size="0.092 0.145" pos="0 0.025 0.137" type="cylinder" rgba="0 0 0 0"/>
          <geom name="iiwa_link_3_visual" type="mesh" mesh="m_link_3" material="iiwa_gray"/>
          <geom name="iiwa_link_3_band" type="mesh" mesh="m_band" material="iiwa_silver"/>
          <geom name="iiwa_link_3_kuka" type="mesh" mesh="m_kuka" material="iiwa_black"/>

          <body name="iiwa_link_4" pos="0 0 0.2155" quat="0.707107 0.707107 0 0">
            <inertial pos="0 0.067 0.034" mass="3.5" diaginertia="0.017 0.0164 0.006"/>
            <joint name="iiwa_joint_4" axis="0 0 1" range="-2.09439510239 2.09439510239" damping="0.5" armature="0.0"/>
            <geom name="iiwa_link_4_geom" size="0.092 0.125" pos="0 0.056 0.025" quat="0.707107 0.707107 0 0" type="cylinder" rgba="0 0 0 0"/>
            <geom name="iiwa_link_4_visual_orange" type="mesh" mesh="m_link_4_orange" material="iiwa_orange"/>
            <geom name="iiwa_link_4_visual_grey" type="mesh" mesh="m_link_4_grey" material="iiwa_gray"/>

            <body name="iiwa_link_5" pos="0 0.1845 0" quat="0 0 0.707107 0.707107">
              <inertial pos="0.0001 0.021 0.076" mass="3.5" diaginertia="0.01 0.0087 0.00449"/>
              <joint name="iiwa_joint_5" axis="0 0 1" range="-2.96705972839 2.96705972839" damping="0.5" armature="0.0"/>
              <geom name="iiwa_link_5_geom" size="0.07 0.145" pos="0 0.03 0.13" quat="0.988771 -0.149438 0 0" type="cylinder" rgba="0 0 0 0"/>
              <geom name="iiwa_link_5_visual" type="mesh" mesh="m_link_5" material="iiwa_gray"/>
              <geom name="iiwa_link_5_band" type="mesh" mesh="m_band" material="iiwa_silver"/>
              <geom name="iiwa_link_5_kuka" type="mesh" mesh="m_kuka" material="iiwa_black"/>

              <body name="iiwa_link_6" pos="0 0 0.2155" quat="0.707107 0.707107 0 0">
                <inertial pos="0 0.0006 0.0004" mass="1.8" diaginertia="0.0049 0.0047 0.0036"/>
                <joint name="iiwa_joint_6" axis="0 0 1" range="-2.09439510239 2.09439510239" damping="0.5" armature="0.0"/>
                <geom name="iiwa_link_6_geom" type="mesh" mesh="m_link_6_orange" material="iiwa_orange"/>
                <geom name="iiwa_link_6_visual_grey" type="mesh" mesh="m_link_6_grey" material="iiwa_gray"/>

                <body name="iiwa_link_7" pos="0 0.081 0" quat="0 0 0.707107 0.707107">
                  <inertial pos="0 0 0.02" mass="1.2" diaginertia="0.001 0.001 0.001"/>
                  <joint name="iiwa_joint_7" axis="0 0 1" range="-3.05432619099 3.05432619099" damping="0.5" armature="0.0"/>
                  <geom name="iiwa_link_7_geom" type="mesh" mesh="m_link_7" material="iiwa_gray"/>

                  <body name="wsg_body" pos="0 0 0.104" quat="0.5 0.5 0.5 0.5">
                    <inertial pos="0 0 0" mass="0.25" diaginertia="0.0004 0.0004 0.0004"/>
                    <geom name="wsg_body_visual" type="mesh" mesh="m_wsg_body" material="wsg_mat"/>
                    <geom name="wsg_body_collision" type="box" size="0.073 0.03625 0.025" contype="0" conaffinity="0" rgba="0 0 0 0"/>

                    <body name="wsg_left_finger" pos="-0.0115 0.028 0" quat="0 0 1 0">
                      <inertial pos="0 0 0" mass="0.06" diaginertia="0.0001 0.0001 0.0001"/>
                      <geom name="wsg_left_finger_visual" type="mesh" mesh="m_wsg_finger" material="wsg_mat"/>
                      <geom name="wsg_left_finger_collision" type="box" pos="-0.008 0.031 0" size="0.006 0.041 0.01"
                            contype="0" conaffinity="0" rgba="0 0 0 0"/>
                    </body>
                    <body name="wsg_right_finger" pos="0.0115 0.028 0">
                      <inertial pos="0 0 0" mass="0.06" diaginertia="0.0001 0.0001 0.0001"/>
                      <geom name="wsg_right_finger_visual" type="mesh" mesh="m_wsg_finger" material="wsg_mat"/>
                      <geom name="wsg_right_finger_collision" type="box" pos="-0.008 0.031 0" size="0.006 0.041 0.01"
                            contype="0" conaffinity="0" rgba="0 0 0 0"/>
                    </body>

                    <body name="paddle_link" pos="0 0.078 -0.23" quat="0.7071067811865476 0 0.7071067811865476 0">
                      <geom name="paddle_geom" type="cylinder" size="0.175 0.005" mass="0.10" material="paddle_mat"
                            contype="1" conaffinity="1" friction="0.3 0.02 0.005" solref="0.015 0.1" condim="6"/>
                      <geom name="paddle_handle_geom" type="box" pos="-0.19 0 0" size="0.0045 0.0375 0.025" mass="0.03" material="wsg_mat"/>
                      <site name="paddle_center" size="0.002" rgba="1 1 0 1"/>
                    </body>
                  </body>
                </body>
              </body>
            </body>
          </body>
        </body>
      </body>
    </body>

    <body name="ball" pos="0.77 -0.03 0.70">
      <freejoint name="ball_freejoint"/>
      <geom name="ball_geom" type="sphere" size="0.02" mass="0.0027" material="ball_mat"
            contype="1" conaffinity="1" friction="0.20 0.003 0.0001" solref="0.015 0.1" condim="6"/>
    </body>
  </worldbody>

  <actuator>
    <motor name="iiwa_torque_1" joint="iiwa_joint_1" ctrlrange="-320 320" gear="1"/>
    <motor name="iiwa_torque_2" joint="iiwa_joint_2" ctrlrange="-320 320" gear="1"/>
    <motor name="iiwa_torque_3" joint="iiwa_joint_3" ctrlrange="-176 176" gear="1"/>
    <motor name="iiwa_torque_4" joint="iiwa_joint_4" ctrlrange="-176 176" gear="1"/>
    <motor name="iiwa_torque_5" joint="iiwa_joint_5" ctrlrange="-110 110" gear="1"/>
    <motor name="iiwa_torque_6" joint="iiwa_joint_6" ctrlrange="-40 40" gear="1"/>
    <motor name="iiwa_torque_7" joint="iiwa_joint_7" ctrlrange="-40 40" gear="1"/>
  </actuator>
</mujoco>